Traceback (most recent call last):
  File "/usr/share/miniconda3/envs/test/lib/python3.8/site-packages/jupyter_cache/executors/utils.py", line 58, in single_nb_execution
    executenb(
  File "/usr/share/miniconda3/envs/test/lib/python3.8/site-packages/nbclient/client.py", line 1204, in execute
    return NotebookClient(nb=nb, resources=resources, km=km, **kwargs).execute()
  File "/usr/share/miniconda3/envs/test/lib/python3.8/site-packages/nbclient/util.py", line 84, in wrapped
    return just_run(coro(*args, **kwargs))
  File "/usr/share/miniconda3/envs/test/lib/python3.8/site-packages/nbclient/util.py", line 62, in just_run
    return loop.run_until_complete(coro)
  File "/usr/share/miniconda3/envs/test/lib/python3.8/asyncio/base_events.py", line 616, in run_until_complete
    return future.result()
  File "/usr/share/miniconda3/envs/test/lib/python3.8/site-packages/nbclient/client.py", line 663, in async_execute
    await self.async_execute_cell(
  File "/usr/share/miniconda3/envs/test/lib/python3.8/site-packages/nbclient/client.py", line 965, in async_execute_cell
    await self._check_raise_for_error(cell, cell_index, exec_reply)
  File "/usr/share/miniconda3/envs/test/lib/python3.8/site-packages/nbclient/client.py", line 862, in _check_raise_for_error
    raise CellExecutionError.from_cell_and_msg(cell, exec_reply_content)
nbclient.exceptions.CellExecutionError: An error occurred while executing the following cell:
------------------
shape = [25, 25, 1]

# Generate network and add geometrical properties
net = op.network.Cubic(shape=shape, spacing=1e-5)
mods = op.models.collections.geometry.spheres_and_cylinders()
net.add_model_collection(mods)
net.regenerate_models()

# Generate phase and add geometry-based thermophysical properties
water = op.phase.Water(network=net)
mods = op.models.collections.physics.basic()
water.add_model_collection(mods)
water.regenerate_models()
------------------

[0;31m---------------------------------------------------------------------------[0m
[0;31mTypeError[0m                                 Traceback (most recent call last)
Input [0;32mIn [2][0m, in [0;36m<cell line: 5>[0;34m()[0m
[1;32m      3[0m [38;5;66;03m# Generate network and add geometrical properties[39;00m
[1;32m      4[0m net [38;5;241m=[39m op[38;5;241m.[39mnetwork[38;5;241m.[39mCubic(shape[38;5;241m=[39mshape, spacing[38;5;241m=[39m[38;5;241m1e-5[39m)
[0;32m----> 5[0m mods [38;5;241m=[39m [43mop[49m[38;5;241;43m.[39;49m[43mmodels[49m[38;5;241;43m.[39;49m[43mcollections[49m[38;5;241;43m.[39;49m[43mgeometry[49m[38;5;241;43m.[39;49m[43mspheres_and_cylinders[49m[43m([49m[43m)[49m
[1;32m      6[0m net[38;5;241m.[39madd_model_collection(mods)
[1;32m      7[0m net[38;5;241m.[39mregenerate_models()

[0;31mTypeError[0m: 'dict' object is not callable
TypeError: 'dict' object is not callable

