Traceback (most recent call last):
  File "/usr/share/miniconda3/envs/test/lib/python3.8/site-packages/jupyter_cache/executors/utils.py", line 58, in single_nb_execution
    executenb(
  File "/usr/share/miniconda3/envs/test/lib/python3.8/site-packages/nbclient/client.py", line 1204, in execute
    return NotebookClient(nb=nb, resources=resources, km=km, **kwargs).execute()
  File "/usr/share/miniconda3/envs/test/lib/python3.8/site-packages/nbclient/util.py", line 84, in wrapped
    return just_run(coro(*args, **kwargs))
  File "/usr/share/miniconda3/envs/test/lib/python3.8/site-packages/nbclient/util.py", line 62, in just_run
    return loop.run_until_complete(coro)
  File "/usr/share/miniconda3/envs/test/lib/python3.8/asyncio/base_events.py", line 616, in run_until_complete
    return future.result()
  File "/usr/share/miniconda3/envs/test/lib/python3.8/site-packages/nbclient/client.py", line 663, in async_execute
    await self.async_execute_cell(
  File "/usr/share/miniconda3/envs/test/lib/python3.8/site-packages/nbclient/client.py", line 965, in async_execute_cell
    await self._check_raise_for_error(cell, cell_index, exec_reply)
  File "/usr/share/miniconda3/envs/test/lib/python3.8/site-packages/nbclient/client.py", line 862, in _check_raise_for_error
    raise CellExecutionError.from_cell_and_msg(cell, exec_reply_content)
nbclient.exceptions.CellExecutionError: An error occurred while executing the following cell:
------------------
import warnings
import numpy as np
import openpnm as op
%config InlineBackend.figure_formats = ['svg']
from openpnm.algorithms import MixedInvasionPercolation as mp
import matplotlib as mpl
import matplotlib.pyplot as plt
from ipywidgets import interact, IntSlider
%load_ext autoreload
%autoreload 2
%matplotlib inline
mpl.rcParams["image.interpolation"] = "None"
warnings.simplefilter("ignore")
np.random.seed(10)
ws = op.Workspace()
ws.settings['loglevel'] = 50
------------------

[0;31m---------------------------------------------------------------------------[0m
[0;31mImportError[0m                               Traceback (most recent call last)
Cell [0;32mIn [1], line 5[0m
[1;32m      3[0m [38;5;28;01mimport[39;00m [38;5;21;01mopenpnm[39;00m [38;5;28;01mas[39;00m [38;5;21;01mop[39;00m
[1;32m      4[0m get_ipython()[38;5;241m.[39mrun_line_magic([38;5;124m'[39m[38;5;124mconfig[39m[38;5;124m'[39m, [38;5;124m"[39m[38;5;124mInlineBackend.figure_formats = [[39m[38;5;124m'[39m[38;5;124msvg[39m[38;5;124m'[39m[38;5;124m][39m[38;5;124m"[39m)
[0;32m----> 5[0m [38;5;28;01mfrom[39;00m [38;5;21;01mopenpnm[39;00m[38;5;21;01m.[39;00m[38;5;21;01malgorithms[39;00m [38;5;28;01mimport[39;00m MixedInvasionPercolation [38;5;28;01mas[39;00m mp
[1;32m      6[0m [38;5;28;01mimport[39;00m [38;5;21;01mmatplotlib[39;00m [38;5;28;01mas[39;00m [38;5;21;01mmpl[39;00m
[1;32m      7[0m [38;5;28;01mimport[39;00m [38;5;21;01mmatplotlib[39;00m[38;5;21;01m.[39;00m[38;5;21;01mpyplot[39;00m [38;5;28;01mas[39;00m [38;5;21;01mplt[39;00m

[0;31mImportError[0m: cannot import name 'MixedInvasionPercolation' from 'openpnm.algorithms' (/home/runner/work/OpenPNM/OpenPNM/openpnm/algorithms/__init__.py)
ImportError: cannot import name 'MixedInvasionPercolation' from 'openpnm.algorithms' (/home/runner/work/OpenPNM/OpenPNM/openpnm/algorithms/__init__.py)

