Traceback (most recent call last):
  File "/usr/share/miniconda3/envs/test/lib/python3.8/site-packages/jupyter_cache/executors/utils.py", line 58, in single_nb_execution
    executenb(
  File "/usr/share/miniconda3/envs/test/lib/python3.8/site-packages/nbclient/client.py", line 1204, in execute
    return NotebookClient(nb=nb, resources=resources, km=km, **kwargs).execute()
  File "/usr/share/miniconda3/envs/test/lib/python3.8/site-packages/nbclient/util.py", line 84, in wrapped
    return just_run(coro(*args, **kwargs))
  File "/usr/share/miniconda3/envs/test/lib/python3.8/site-packages/nbclient/util.py", line 62, in just_run
    return loop.run_until_complete(coro)
  File "/usr/share/miniconda3/envs/test/lib/python3.8/asyncio/base_events.py", line 616, in run_until_complete
    return future.result()
  File "/usr/share/miniconda3/envs/test/lib/python3.8/site-packages/nbclient/client.py", line 663, in async_execute
    await self.async_execute_cell(
  File "/usr/share/miniconda3/envs/test/lib/python3.8/site-packages/nbclient/client.py", line 965, in async_execute_cell
    await self._check_raise_for_error(cell, cell_index, exec_reply)
  File "/usr/share/miniconda3/envs/test/lib/python3.8/site-packages/nbclient/client.py", line 862, in _check_raise_for_error
    raise CellExecutionError.from_cell_and_msg(cell, exec_reply_content)
nbclient.exceptions.CellExecutionError: An error occurred while executing the following cell:
------------------
pn['pore.concentration'] = rx['pore.concentration']
fig, ax = plt.subplots(figsize=[15, 15])
op.topotools.plot_connections(network=pn, color='k', alpha=.2, ax=ax)
op.topotools.plot_coordinates(network=pn, color_by=pn['pore.concentration'],
                              size_by=pn['pore.diameter'], cmap='plasma',
                              ax=ax, markersize=100)
_ = plt.axis('off')
------------------

[0;31m---------------------------------------------------------------------------[0m
[0;31mAttributeError[0m                            Traceback (most recent call last)
Cell [0;32mIn [6], line 3[0m
[1;32m      1[0m pn[[38;5;124m'[39m[38;5;124mpore.concentration[39m[38;5;124m'[39m] [38;5;241m=[39m rx[[38;5;124m'[39m[38;5;124mpore.concentration[39m[38;5;124m'[39m]
[1;32m      2[0m fig, ax [38;5;241m=[39m plt[38;5;241m.[39msubplots(figsize[38;5;241m=[39m[[38;5;241m15[39m, [38;5;241m15[39m])
[0;32m----> 3[0m [43mop[49m[38;5;241;43m.[39;49m[43mtopotools[49m[38;5;241;43m.[39;49m[43mplot_connections[49m(network[38;5;241m=[39mpn, color[38;5;241m=[39m[38;5;124m'[39m[38;5;124mk[39m[38;5;124m'[39m, alpha[38;5;241m=[39m[38;5;241m.2[39m, ax[38;5;241m=[39max)
[1;32m      4[0m op[38;5;241m.[39mtopotools[38;5;241m.[39mplot_coordinates(network[38;5;241m=[39mpn, color_by[38;5;241m=[39mpn[[38;5;124m'[39m[38;5;124mpore.concentration[39m[38;5;124m'[39m],
[1;32m      5[0m                               size_by[38;5;241m=[39mpn[[38;5;124m'[39m[38;5;124mpore.diameter[39m[38;5;124m'[39m], cmap[38;5;241m=[39m[38;5;124m'[39m[38;5;124mplasma[39m[38;5;124m'[39m,
[1;32m      6[0m                               ax[38;5;241m=[39max, markersize[38;5;241m=[39m[38;5;241m100[39m)
[1;32m      7[0m _ [38;5;241m=[39m plt[38;5;241m.[39maxis([38;5;124m'[39m[38;5;124moff[39m[38;5;124m'[39m)

[0;31mAttributeError[0m: module 'openpnm.topotools' has no attribute 'plot_connections'
AttributeError: module 'openpnm.topotools' has no attribute 'plot_connections'

