Traceback (most recent call last):
  File "/usr/share/miniconda3/envs/test/lib/python3.8/site-packages/jupyter_cache/executors/utils.py", line 58, in single_nb_execution
    executenb(
  File "/usr/share/miniconda3/envs/test/lib/python3.8/site-packages/nbclient/client.py", line 1204, in execute
    return NotebookClient(nb=nb, resources=resources, km=km, **kwargs).execute()
  File "/usr/share/miniconda3/envs/test/lib/python3.8/site-packages/nbclient/util.py", line 84, in wrapped
    return just_run(coro(*args, **kwargs))
  File "/usr/share/miniconda3/envs/test/lib/python3.8/site-packages/nbclient/util.py", line 62, in just_run
    return loop.run_until_complete(coro)
  File "/usr/share/miniconda3/envs/test/lib/python3.8/asyncio/base_events.py", line 616, in run_until_complete
    return future.result()
  File "/usr/share/miniconda3/envs/test/lib/python3.8/site-packages/nbclient/client.py", line 663, in async_execute
    await self.async_execute_cell(
  File "/usr/share/miniconda3/envs/test/lib/python3.8/site-packages/nbclient/client.py", line 965, in async_execute_cell
    await self._check_raise_for_error(cell, cell_index, exec_reply)
  File "/usr/share/miniconda3/envs/test/lib/python3.8/site-packages/nbclient/client.py", line 862, in _check_raise_for_error
    raise CellExecutionError.from_cell_and_msg(cell, exec_reply_content)
nbclient.exceptions.CellExecutionError: An error occurred while executing the following cell:
------------------
Ps_front = pn.pores(['front'])
Ts_front = pn.find_neighbor_throats(pores=Ps_front, mode='xor')
steps = tspan[1]/saveat + 1
count = 0
c_avg = []

for ti in soln['pore.concentration'].t:
    c_front = soln['pore.concentration'](ti)[Ps_front]
    q_front = sf.rate(throats=pn.Ts,mode='single')[Ts_front]
    c_avg.append((q_front*c_front).sum() / q_front.sum())

fig, ax = plt.subplots()    
ax.plot(soln['pore.concentration'].t, c_avg, "o-")
ax.legend(('simulation', 'fitted'))
ax.set_xlabel('time (s)')
ax.set_ylabel('concentration');
------------------

[0;31m---------------------------------------------------------------------------[0m
[0;31mTypeError[0m                                 Traceback (most recent call last)
Cell [0;32mIn [7], line 7[0m
[1;32m      4[0m count [38;5;241m=[39m [38;5;241m0[39m
[1;32m      5[0m c_avg [38;5;241m=[39m []
[0;32m----> 7[0m [38;5;28;01mfor[39;00m ti [38;5;129;01min[39;00m [43msoln[49m[43m[[49m[38;5;124;43m'[39;49m[38;5;124;43mpore.concentration[39;49m[38;5;124;43m'[39;49m[43m][49m[38;5;241m.[39mt:
[1;32m      8[0m     c_front [38;5;241m=[39m soln[[38;5;124m'[39m[38;5;124mpore.concentration[39m[38;5;124m'[39m](ti)[Ps_front]
[1;32m      9[0m     q_front [38;5;241m=[39m sf[38;5;241m.[39mrate(throats[38;5;241m=[39mpn[38;5;241m.[39mTs,mode[38;5;241m=[39m[38;5;124m'[39m[38;5;124msingle[39m[38;5;124m'[39m)[Ts_front]

[0;31mTypeError[0m: 'NoneType' object is not subscriptable
TypeError: 'NoneType' object is not subscriptable

