Traceback (most recent call last):
  File "/usr/share/miniconda3/envs/test/lib/python3.8/site-packages/jupyter_cache/executors/utils.py", line 58, in single_nb_execution
    executenb(
  File "/usr/share/miniconda3/envs/test/lib/python3.8/site-packages/nbclient/client.py", line 1204, in execute
    return NotebookClient(nb=nb, resources=resources, km=km, **kwargs).execute()
  File "/usr/share/miniconda3/envs/test/lib/python3.8/site-packages/nbclient/util.py", line 84, in wrapped
    return just_run(coro(*args, **kwargs))
  File "/usr/share/miniconda3/envs/test/lib/python3.8/site-packages/nbclient/util.py", line 62, in just_run
    return loop.run_until_complete(coro)
  File "/usr/share/miniconda3/envs/test/lib/python3.8/asyncio/base_events.py", line 616, in run_until_complete
    return future.result()
  File "/usr/share/miniconda3/envs/test/lib/python3.8/site-packages/nbclient/client.py", line 663, in async_execute
    await self.async_execute_cell(
  File "/usr/share/miniconda3/envs/test/lib/python3.8/site-packages/nbclient/client.py", line 965, in async_execute_cell
    await self._check_raise_for_error(cell, cell_index, exec_reply)
  File "/usr/share/miniconda3/envs/test/lib/python3.8/site-packages/nbclient/client.py", line 862, in _check_raise_for_error
    raise CellExecutionError.from_cell_and_msg(cell, exec_reply_content)
nbclient.exceptions.CellExecutionError: An error occurred while executing the following cell:
------------------
fig, ax = plt.subplots(figsize=[5, 5])
op.visualization.plot_coordinates(ax=fig,
                                  network=pn,
                                  size_by=pn["pore.diameter"],
                                  color_by=Diff["pore.concentration"], 
                                  markersize=100)
_ = plt.axis('off')
------------------

[0;31m---------------------------------------------------------------------------[0m
[0;31mAttributeError[0m                            Traceback (most recent call last)
Cell [0;32mIn [5], line 2[0m
[1;32m      1[0m fig, ax [38;5;241m=[39m plt[38;5;241m.[39msubplots(figsize[38;5;241m=[39m[[38;5;241m5[39m, [38;5;241m5[39m])
[0;32m----> 2[0m op[38;5;241m.[39mvisualization[38;5;241m.[39mplot_coordinates(ax[38;5;241m=[39mfig,
[1;32m      3[0m                                   network[38;5;241m=[39mpn,
[1;32m      4[0m                                   size_by[38;5;241m=[39mpn[[38;5;124m"[39m[38;5;124mpore.diameter[39m[38;5;124m"[39m],
[1;32m      5[0m                                   color_by[38;5;241m=[39mDiff[[38;5;124m"[39m[38;5;124mpore.concentration[39m[38;5;124m"[39m], 
[1;32m      6[0m                                   markersize[38;5;241m=[39m[38;5;241m100[39m)
[1;32m      7[0m _ [38;5;241m=[39m plt[38;5;241m.[39maxis([38;5;124m'[39m[38;5;124moff[39m[38;5;124m'[39m)

File [0;32m~/work/OpenPNM/OpenPNM/openpnm/visualization/_plottools.py:283[0m, in [0;36mplot_coordinates[0;34m(network, pores, ax, size_by, color_by, cmap, color, alpha, marker, markersize, **kwargs)[0m
[1;32m    280[0m [38;5;28;01melse[39;00m:
[1;32m    281[0m     [38;5;66;03m# The next line is necessary if ax was created using plt.subplots()[39;00m
[1;32m    282[0m     fig, ax [38;5;241m=[39m ax[38;5;241m.[39mget_figure(), ax
[0;32m--> 283[0m [38;5;28;01mif[39;00m ThreeD [38;5;129;01mand[39;00m [43max[49m[38;5;241;43m.[39;49m[43mname[49m [38;5;241m!=[39m [38;5;124m'[39m[38;5;124m3d[39m[38;5;124m'[39m:
[1;32m    284[0m     fig[38;5;241m.[39mdelaxes(ax)
[1;32m    285[0m     ax [38;5;241m=[39m fig[38;5;241m.[39madd_subplot([38;5;241m111[39m, projection[38;5;241m=[39m[38;5;124m'[39m[38;5;124m3d[39m[38;5;124m'[39m)

[0;31mAttributeError[0m: 'Figure' object has no attribute 'name'
AttributeError: 'Figure' object has no attribute 'name'

