Traceback (most recent call last):
  File "/usr/share/miniconda3/envs/test/lib/python3.8/site-packages/jupyter_cache/executors/utils.py", line 58, in single_nb_execution
    executenb(
  File "/usr/share/miniconda3/envs/test/lib/python3.8/site-packages/nbclient/client.py", line 1204, in execute
    return NotebookClient(nb=nb, resources=resources, km=km, **kwargs).execute()
  File "/usr/share/miniconda3/envs/test/lib/python3.8/site-packages/nbclient/util.py", line 84, in wrapped
    return just_run(coro(*args, **kwargs))
  File "/usr/share/miniconda3/envs/test/lib/python3.8/site-packages/nbclient/util.py", line 62, in just_run
    return loop.run_until_complete(coro)
  File "/usr/share/miniconda3/envs/test/lib/python3.8/asyncio/base_events.py", line 616, in run_until_complete
    return future.result()
  File "/usr/share/miniconda3/envs/test/lib/python3.8/site-packages/nbclient/client.py", line 663, in async_execute
    await self.async_execute_cell(
  File "/usr/share/miniconda3/envs/test/lib/python3.8/site-packages/nbclient/client.py", line 965, in async_execute_cell
    await self._check_raise_for_error(cell, cell_index, exec_reply)
  File "/usr/share/miniconda3/envs/test/lib/python3.8/site-packages/nbclient/client.py", line 862, in _check_raise_for_error
    raise CellExecutionError.from_cell_and_msg(cell, exec_reply_content)
nbclient.exceptions.CellExecutionError: An error occurred while executing the following cell:
------------------
pn = op.network.Voronoi(points=100, shape=[1, 1, 1])
pn['pore.diameter'] = np.random.rand(pn.Np)
ax = op.visualization.plot_notebook(pn, node_color=pn['pore.diameter'], node_size=pn['pore.diameter'], node_scale=50)
ax.show()
------------------

[0;31m---------------------------------------------------------------------------[0m
[0;31mModuleNotFoundError[0m                       Traceback (most recent call last)
File [0;32m~/work/OpenPNM/OpenPNM/openpnm/visualization/_plottools.py:570[0m, in [0;36mplot_notebook[0;34m(network, node_color, edge_color, node_size, node_scale, edge_scale, colormap)[0m
[1;32m    569[0m [38;5;28;01mtry[39;00m:
[0;32m--> 570[0m     [38;5;28;01mimport[39;00m [38;5;21;01mplotly[39;00m[38;5;21;01m.[39;00m[38;5;21;01mgraph_objects[39;00m [38;5;28;01mas[39;00m [38;5;21;01mgo[39;00m
[1;32m    571[0m [38;5;28;01mexcept[39;00m [38;5;167;01mImportError[39;00m:

[0;31mModuleNotFoundError[0m: No module named 'plotly'

During handling of the above exception, another exception occurred:

[0;31mException[0m                                 Traceback (most recent call last)
Input [0;32mIn [21][0m, in [0;36m<cell line: 3>[0;34m()[0m
[1;32m      1[0m pn [38;5;241m=[39m op[38;5;241m.[39mnetwork[38;5;241m.[39mVoronoi(points[38;5;241m=[39m[38;5;241m100[39m, shape[38;5;241m=[39m[[38;5;241m1[39m, [38;5;241m1[39m, [38;5;241m1[39m])
[1;32m      2[0m pn[[38;5;124m'[39m[38;5;124mpore.diameter[39m[38;5;124m'[39m] [38;5;241m=[39m np[38;5;241m.[39mrandom[38;5;241m.[39mrand(pn[38;5;241m.[39mNp)
[0;32m----> 3[0m ax [38;5;241m=[39m [43mop[49m[38;5;241;43m.[39;49m[43mvisualization[49m[38;5;241;43m.[39;49m[43mplot_notebook[49m[43m([49m[43mpn[49m[43m,[49m[43m [49m[43mnode_color[49m[38;5;241;43m=[39;49m[43mpn[49m[43m[[49m[38;5;124;43m'[39;49m[38;5;124;43mpore.diameter[39;49m[38;5;124;43m'[39;49m[43m][49m[43m,[49m[43m [49m[43mnode_size[49m[38;5;241;43m=[39;49m[43mpn[49m[43m[[49m[38;5;124;43m'[39;49m[38;5;124;43mpore.diameter[39;49m[38;5;124;43m'[39;49m[43m][49m[43m,[49m[43m [49m[43mnode_scale[49m[38;5;241;43m=[39;49m[38;5;241;43m50[39;49m[43m)[49m
[1;32m      4[0m ax[38;5;241m.[39mshow()

File [0;32m~/work/OpenPNM/OpenPNM/openpnm/visualization/_plottools.py:572[0m, in [0;36mplot_notebook[0;34m(network, node_color, edge_color, node_size, node_scale, edge_scale, colormap)[0m
[1;32m    570[0m     [38;5;28;01mimport[39;00m [38;5;21;01mplotly[39;00m[38;5;21;01m.[39;00m[38;5;21;01mgraph_objects[39;00m [38;5;28;01mas[39;00m [38;5;21;01mgo[39;00m
[1;32m    571[0m [38;5;28;01mexcept[39;00m [38;5;167;01mImportError[39;00m:
[0;32m--> 572[0m     [38;5;28;01mraise[39;00m [38;5;167;01mException[39;00m([38;5;124m'[39m[38;5;124mPlotly is not installed.[39m[38;5;124m'[39m
[1;32m    573[0m                     [38;5;124m'[39m[38;5;124mPlease install Plotly using [39m[38;5;124m"[39m[38;5;124mpip install plotly[39m[38;5;124m"[39m[38;5;124m'[39m)
[1;32m    575[0m [38;5;66;03m# Get xyz coords for points[39;00m
[1;32m    576[0m x_nodes, y_nodes, z_nodes [38;5;241m=[39m network[38;5;241m.[39mcoords[38;5;241m.[39mT

[0;31mException[0m: Plotly is not installed.Please install Plotly using "pip install plotly"
Exception: Plotly is not installed.Please install Plotly using "pip install plotly"

