Traceback (most recent call last):
  File "/usr/share/miniconda3/envs/test/lib/python3.8/site-packages/jupyter_cache/executors/utils.py", line 58, in single_nb_execution
    executenb(
  File "/usr/share/miniconda3/envs/test/lib/python3.8/site-packages/nbclient/client.py", line 1204, in execute
    return NotebookClient(nb=nb, resources=resources, km=km, **kwargs).execute()
  File "/usr/share/miniconda3/envs/test/lib/python3.8/site-packages/nbclient/util.py", line 84, in wrapped
    return just_run(coro(*args, **kwargs))
  File "/usr/share/miniconda3/envs/test/lib/python3.8/site-packages/nbclient/util.py", line 62, in just_run
    return loop.run_until_complete(coro)
  File "/usr/share/miniconda3/envs/test/lib/python3.8/asyncio/base_events.py", line 616, in run_until_complete
    return future.result()
  File "/usr/share/miniconda3/envs/test/lib/python3.8/site-packages/nbclient/client.py", line 663, in async_execute
    await self.async_execute_cell(
  File "/usr/share/miniconda3/envs/test/lib/python3.8/site-packages/nbclient/client.py", line 965, in async_execute_cell
    await self._check_raise_for_error(cell, cell_index, exec_reply)
  File "/usr/share/miniconda3/envs/test/lib/python3.8/site-packages/nbclient/client.py", line 862, in _check_raise_for_error
    raise CellExecutionError.from_cell_and_msg(cell, exec_reply_content)
nbclient.exceptions.CellExecutionError: An error occurred while executing the following cell:
------------------
print(pn.models['pore.diameter@all'])
------------------

[0;31m---------------------------------------------------------------------------[0m
[0;31mKeyError[0m                                  Traceback (most recent call last)
File [0;32m~/work/OpenPNM/OpenPNM/openpnm/core/_models.py:211[0m, in [0;36mModelsDict.__getitem__[0;34m(self, key)[0m
[1;32m    210[0m [38;5;28;01mtry[39;00m:
[0;32m--> 211[0m     [38;5;28;01mreturn[39;00m [38;5;28;43msuper[39;49m[43m([49m[43m)[49m[38;5;241;43m.[39;49m[38;5;21;43m__getitem__[39;49m[43m([49m[43mkey[49m[43m)[49m
[1;32m    212[0m [38;5;28;01mexcept[39;00m [38;5;167;01mKeyError[39;00m:

[0;31mKeyError[0m: 'pore.diameter@all'

During handling of the above exception, another exception occurred:

[0;31mKeyError[0m                                  Traceback (most recent call last)
Input [0;32mIn [30][0m, in [0;36m<cell line: 1>[0;34m()[0m
[0;32m----> 1[0m [38;5;28mprint[39m([43mpn[49m[38;5;241;43m.[39;49m[43mmodels[49m[43m[[49m[38;5;124;43m'[39;49m[38;5;124;43mpore.diameter@all[39;49m[38;5;124;43m'[39;49m[43m][49m)

File [0;32m~/work/OpenPNM/OpenPNM/openpnm/core/_models.py:220[0m, in [0;36mModelsDict.__getitem__[0;34m(self, key)[0m
[1;32m    218[0m     [38;5;28;01mreturn[39;00m d
[1;32m    219[0m [38;5;28;01melse[39;00m:
[0;32m--> 220[0m     [38;5;28;01mraise[39;00m [38;5;167;01mKeyError[39;00m(key)

[0;31mKeyError[0m: 'pore.diameter@all'
KeyError: 'pore.diameter@all'

